[2025-09-06T06:20:23.381+0000] {taskinstance.py:1125} INFO - Dependencies all met for dep_context=non-requeueable deps ti=<TaskInstance: mysql_insert_select.read_data scheduled__2023-01-01T00:00:00+00:00 [queued]>
[2025-09-06T06:20:23.395+0000] {taskinstance.py:1125} INFO - Dependencies all met for dep_context=requeueable deps ti=<TaskInstance: mysql_insert_select.read_data scheduled__2023-01-01T00:00:00+00:00 [queued]>
[2025-09-06T06:20:23.396+0000] {taskinstance.py:1331} INFO - Starting attempt 1 of 1
[2025-09-06T06:20:23.419+0000] {taskinstance.py:1350} INFO - Executing <Task(PythonOperator): read_data> on 2023-01-01 00:00:00+00:00
[2025-09-06T06:20:23.434+0000] {standard_task_runner.py:57} INFO - Started process 781 to run task
[2025-09-06T06:20:23.440+0000] {standard_task_runner.py:84} INFO - Running: ['***', 'tasks', 'run', 'mysql_insert_select', 'read_data', 'scheduled__2023-01-01T00:00:00+00:00', '--job-id', '346', '--raw', '--subdir', 'DAGS_FOLDER/mysql_insert_select.py', '--cfg-path', '/tmp/tmpzfpu6s_d']
[2025-09-06T06:20:23.448+0000] {standard_task_runner.py:85} INFO - Job 346: Subtask read_data
[2025-09-06T06:20:23.536+0000] {task_command.py:410} INFO - Running <TaskInstance: mysql_insert_select.read_data scheduled__2023-01-01T00:00:00+00:00 [running]> on host 498c9c87b7f1
[2025-09-06T06:20:23.666+0000] {taskinstance.py:1570} INFO - Exporting env vars: AIRFLOW_CTX_DAG_OWNER='***' AIRFLOW_CTX_DAG_ID='mysql_insert_select' AIRFLOW_CTX_TASK_ID='read_data' AIRFLOW_CTX_EXECUTION_DATE='2023-01-01T00:00:00+00:00' AIRFLOW_CTX_TRY_NUMBER='1' AIRFLOW_CTX_DAG_RUN_ID='scheduled__2023-01-01T00:00:00+00:00'
[2025-09-06T06:20:23.682+0000] {base.py:73} INFO - Using connection ID 'mysql_conn' for task execution.
[2025-09-06T06:20:23.703+0000] {taskinstance.py:1847} ERROR - Task failed with exception
Traceback (most recent call last):
  File "/home/airflow/.local/lib/python3.7/site-packages/pandas/io/sql.py", line 2056, in execute
    cur.execute(*args, **kwargs)
  File "/home/airflow/.local/lib/python3.7/site-packages/MySQLdb/cursors.py", line 206, in execute
    res = self._query(query)
  File "/home/airflow/.local/lib/python3.7/site-packages/MySQLdb/cursors.py", line 319, in _query
    db.query(q)
  File "/home/airflow/.local/lib/python3.7/site-packages/MySQLdb/connections.py", line 254, in query
    _mysql.connection.query(self, query)
MySQLdb.ProgrammingError: (1146, "Table 'my_app_db.penguins_raw' doesn't exist")

The above exception was the direct cause of the following exception:

Traceback (most recent call last):
  File "/home/airflow/.local/lib/python3.7/site-packages/airflow/operators/python.py", line 181, in execute
    return_value = self.execute_callable()
  File "/home/airflow/.local/lib/python3.7/site-packages/airflow/operators/python.py", line 198, in execute_callable
    return self.python_callable(*self.op_args, **self.op_kwargs)
  File "/opt/airflow/dags/scripts/funciones.py", line 82, in read_data
    df = hook.get_pandas_df(sql=query)
  File "/home/airflow/.local/lib/python3.7/site-packages/airflow/providers/common/sql/hooks/sql.py", line 201, in get_pandas_df
    return psql.read_sql(sql, con=conn, params=parameters, **kwargs)
  File "/home/airflow/.local/lib/python3.7/site-packages/pandas/io/sql.py", line 608, in read_sql
    chunksize=chunksize,
  File "/home/airflow/.local/lib/python3.7/site-packages/pandas/io/sql.py", line 2116, in read_query
    cursor = self.execute(*args)
  File "/home/airflow/.local/lib/python3.7/site-packages/pandas/io/sql.py", line 2068, in execute
    raise ex from exc
pandas.io.sql.DatabaseError: Execution failed on sql 'SELECT * FROM penguins_raw': (1146, "Table 'my_app_db.penguins_raw' doesn't exist")
[2025-09-06T06:20:23.717+0000] {taskinstance.py:1373} INFO - Marking task as FAILED. dag_id=mysql_insert_select, task_id=read_data, execution_date=20230101T000000, start_date=20250906T062023, end_date=20250906T062023
[2025-09-06T06:20:23.736+0000] {standard_task_runner.py:109} ERROR - Failed to execute job 346 for task read_data (Execution failed on sql 'SELECT * FROM penguins_raw': (1146, "Table 'my_app_db.penguins_raw' doesn't exist"); 781)
[2025-09-06T06:20:23.775+0000] {local_task_job_runner.py:232} INFO - Task exited with return code 1
[2025-09-06T06:20:23.833+0000] {taskinstance.py:2674} INFO - 0 downstream tasks scheduled from follow-on schedule check
