[2025-09-05T21:59:40.169+0000] {taskinstance.py:1125} INFO - Dependencies all met for dep_context=non-requeueable deps ti=<TaskInstance: mysql_insert_select.insert_penguins manual__2025-09-05T21:59:33.550865+00:00 [queued]>
[2025-09-05T21:59:40.183+0000] {taskinstance.py:1125} INFO - Dependencies all met for dep_context=requeueable deps ti=<TaskInstance: mysql_insert_select.insert_penguins manual__2025-09-05T21:59:33.550865+00:00 [queued]>
[2025-09-05T21:59:40.183+0000] {taskinstance.py:1331} INFO - Starting attempt 1 of 1
[2025-09-05T21:59:40.202+0000] {taskinstance.py:1350} INFO - Executing <Task(PythonOperator): insert_penguins> on 2025-09-05 21:59:33.550865+00:00
[2025-09-05T21:59:40.212+0000] {standard_task_runner.py:57} INFO - Started process 1333 to run task
[2025-09-05T21:59:40.218+0000] {standard_task_runner.py:84} INFO - Running: ['***', 'tasks', 'run', 'mysql_insert_select', 'insert_penguins', 'manual__2025-09-05T21:59:33.550865+00:00', '--job-id', '18', '--raw', '--subdir', 'DAGS_FOLDER/crea_tablas.py', '--cfg-path', '/tmp/tmp2us4r_6p']
[2025-09-05T21:59:40.221+0000] {standard_task_runner.py:85} INFO - Job 18: Subtask insert_penguins
[2025-09-05T21:59:40.303+0000] {task_command.py:410} INFO - Running <TaskInstance: mysql_insert_select.insert_penguins manual__2025-09-05T21:59:33.550865+00:00 [running]> on host 72c5ffe25b48
[2025-09-05T21:59:40.451+0000] {taskinstance.py:1570} INFO - Exporting env vars: AIRFLOW_CTX_DAG_OWNER='***' AIRFLOW_CTX_DAG_ID='mysql_insert_select' AIRFLOW_CTX_TASK_ID='insert_penguins' AIRFLOW_CTX_EXECUTION_DATE='2025-09-05T21:59:33.550865+00:00' AIRFLOW_CTX_TRY_NUMBER='1' AIRFLOW_CTX_DAG_RUN_ID='manual__2025-09-05T21:59:33.550865+00:00'
[2025-09-05T21:59:40.453+0000] {taskinstance.py:1847} ERROR - Task failed with exception
Traceback (most recent call last):
  File "/home/airflow/.local/lib/python3.7/site-packages/airflow/operators/python.py", line 181, in execute
    return_value = self.execute_callable()
  File "/home/airflow/.local/lib/python3.7/site-packages/airflow/operators/python.py", line 198, in execute_callable
    return self.python_callable(*self.op_args, **self.op_kwargs)
  File "/opt/airflow/dags/crea_tablas.py", line 27, in insert_data
    hook = MySqlHook(mysql_conn_id=CONN_ID)
NameError: name 'MySqlHook' is not defined
[2025-09-05T21:59:40.473+0000] {taskinstance.py:1373} INFO - Marking task as FAILED. dag_id=mysql_insert_select, task_id=insert_penguins, execution_date=20250905T215933, start_date=20250905T215940, end_date=20250905T215940
[2025-09-05T21:59:40.502+0000] {standard_task_runner.py:109} ERROR - Failed to execute job 18 for task insert_penguins (name 'MySqlHook' is not defined; 1333)
[2025-09-05T21:59:40.551+0000] {local_task_job_runner.py:232} INFO - Task exited with return code 1
[2025-09-05T21:59:40.607+0000] {taskinstance.py:2674} INFO - 0 downstream tasks scheduled from follow-on schedule check
