[2025-09-06T06:48:09.965+0000] {taskinstance.py:1125} INFO - Dependencies all met for dep_context=non-requeueable deps ti=<TaskInstance: mysql_insert_select.setup_fastapi manual__2025-09-06T06:47:47.977199+00:00 [queued]>
[2025-09-06T06:48:09.992+0000] {taskinstance.py:1125} INFO - Dependencies all met for dep_context=requeueable deps ti=<TaskInstance: mysql_insert_select.setup_fastapi manual__2025-09-06T06:47:47.977199+00:00 [queued]>
[2025-09-06T06:48:09.992+0000] {taskinstance.py:1331} INFO - Starting attempt 1 of 1
[2025-09-06T06:48:10.013+0000] {taskinstance.py:1350} INFO - Executing <Task(PythonOperator): setup_fastapi> on 2025-09-06 06:47:47.977199+00:00
[2025-09-06T06:48:10.028+0000] {standard_task_runner.py:57} INFO - Started process 219 to run task
[2025-09-06T06:48:10.034+0000] {standard_task_runner.py:84} INFO - Running: ['***', 'tasks', 'run', 'mysql_insert_select', 'setup_fastapi', 'manual__2025-09-06T06:47:47.977199+00:00', '--job-id', '422', '--raw', '--subdir', 'DAGS_FOLDER/mysql_insert_select.py', '--cfg-path', '/tmp/tmpf08lpiej']
[2025-09-06T06:48:10.037+0000] {standard_task_runner.py:85} INFO - Job 422: Subtask setup_fastapi
[2025-09-06T06:48:10.130+0000] {task_command.py:410} INFO - Running <TaskInstance: mysql_insert_select.setup_fastapi manual__2025-09-06T06:47:47.977199+00:00 [running]> on host b4d48ea8f1b7
[2025-09-06T06:48:10.295+0000] {taskinstance.py:1570} INFO - Exporting env vars: AIRFLOW_CTX_DAG_OWNER='***' AIRFLOW_CTX_DAG_ID='mysql_insert_select' AIRFLOW_CTX_TASK_ID='setup_fastapi' AIRFLOW_CTX_EXECUTION_DATE='2025-09-06T06:47:47.977199+00:00' AIRFLOW_CTX_TRY_NUMBER='1' AIRFLOW_CTX_DAG_RUN_ID='manual__2025-09-06T06:47:47.977199+00:00'
[2025-09-06T06:48:10.297+0000] {logging_mixin.py:149} INFO -  Configuraci√≥n de FastAPI lista:
[2025-09-06T06:48:10.297+0000] {logging_mixin.py:149} INFO -    - Modelo: /opt/***/models/RegresionLogistica.pkl
[2025-09-06T06:48:10.298+0000] {logging_mixin.py:149} INFO -    - App: /opt/***/dags/fastapi_app.py
[2025-09-06T06:48:10.298+0000] {logging_mixin.py:149} INFO -    - Puerto sugerido: 8000
[2025-09-06T06:48:10.298+0000] {logging_mixin.py:149} INFO -    - Comando sugerido: uvicorn fastapi_app:app --host 0.0.0.0 --port 8000
[2025-09-06T06:48:10.299+0000] {logging_mixin.py:149} INFO - Error configurando FastAPI: name 'datetime' is not defined
[2025-09-06T06:48:10.299+0000] {taskinstance.py:1847} ERROR - Task failed with exception
Traceback (most recent call last):
  File "/home/airflow/.local/lib/python3.7/site-packages/airflow/operators/python.py", line 181, in execute
    return_value = self.execute_callable()
  File "/home/airflow/.local/lib/python3.7/site-packages/airflow/operators/python.py", line 198, in execute_callable
    return self.python_callable(*self.op_args, **self.op_kwargs)
  File "/opt/airflow/dags/scripts/funciones.py", line 174, in start_fastapi_server
    f.write(f"FastAPI ready at {datetime.now()}\n")
NameError: name 'datetime' is not defined
[2025-09-06T06:48:10.311+0000] {taskinstance.py:1373} INFO - Marking task as FAILED. dag_id=mysql_insert_select, task_id=setup_fastapi, execution_date=20250906T064747, start_date=20250906T064809, end_date=20250906T064810
[2025-09-06T06:48:10.328+0000] {standard_task_runner.py:109} ERROR - Failed to execute job 422 for task setup_fastapi (name 'datetime' is not defined; 219)
[2025-09-06T06:48:10.370+0000] {local_task_job_runner.py:232} INFO - Task exited with return code 1
[2025-09-06T06:48:10.414+0000] {taskinstance.py:2674} INFO - 0 downstream tasks scheduled from follow-on schedule check
