[2025-09-06T04:53:11.498+0000] {taskinstance.py:1125} INFO - Dependencies all met for dep_context=non-requeueable deps ti=<TaskInstance: mysql_insert_select.train_model manual__2025-09-06T04:52:57.019954+00:00 [queued]>
[2025-09-06T04:53:11.514+0000] {taskinstance.py:1125} INFO - Dependencies all met for dep_context=requeueable deps ti=<TaskInstance: mysql_insert_select.train_model manual__2025-09-06T04:52:57.019954+00:00 [queued]>
[2025-09-06T04:53:11.514+0000] {taskinstance.py:1331} INFO - Starting attempt 1 of 1
[2025-09-06T04:53:11.536+0000] {taskinstance.py:1350} INFO - Executing <Task(PythonOperator): train_model> on 2025-09-06 04:52:57.019954+00:00
[2025-09-06T04:53:11.549+0000] {standard_task_runner.py:57} INFO - Started process 763 to run task
[2025-09-06T04:53:11.559+0000] {standard_task_runner.py:84} INFO - Running: ['***', 'tasks', 'run', 'mysql_insert_select', 'train_model', 'manual__2025-09-06T04:52:57.019954+00:00', '--job-id', '221', '--raw', '--subdir', 'DAGS_FOLDER/mysql_insert_select.py', '--cfg-path', '/tmp/tmpgy9nyn9_']
[2025-09-06T04:53:11.565+0000] {standard_task_runner.py:85} INFO - Job 221: Subtask train_model
[2025-09-06T04:53:11.645+0000] {task_command.py:410} INFO - Running <TaskInstance: mysql_insert_select.train_model manual__2025-09-06T04:52:57.019954+00:00 [running]> on host 6faa580ba6cb
[2025-09-06T04:53:11.781+0000] {taskinstance.py:1570} INFO - Exporting env vars: AIRFLOW_CTX_DAG_OWNER='***' AIRFLOW_CTX_DAG_ID='mysql_insert_select' AIRFLOW_CTX_TASK_ID='train_model' AIRFLOW_CTX_EXECUTION_DATE='2025-09-06T04:52:57.019954+00:00' AIRFLOW_CTX_TRY_NUMBER='1' AIRFLOW_CTX_DAG_RUN_ID='manual__2025-09-06T04:52:57.019954+00:00'
[2025-09-06T04:53:11.801+0000] {base.py:73} INFO - Using connection ID 'mysql_conn' for task execution.
[2025-09-06T04:53:11.834+0000] {taskinstance.py:1847} ERROR - Task failed with exception
Traceback (most recent call last):
  File "/home/airflow/.local/lib/python3.7/site-packages/airflow/operators/python.py", line 181, in execute
    return_value = self.execute_callable()
  File "/home/airflow/.local/lib/python3.7/site-packages/airflow/operators/python.py", line 198, in execute_callable
    return self.python_callable(*self.op_args, **self.op_kwargs)
  File "/opt/airflow/dags/scripts/funciones.py", line 141, in train_model
    model = LogisticRegression(max_iter=1000, random_state=42)
NameError: name 'LogisticRegression' is not defined
[2025-09-06T04:53:11.852+0000] {taskinstance.py:1373} INFO - Marking task as FAILED. dag_id=mysql_insert_select, task_id=train_model, execution_date=20250906T045257, start_date=20250906T045311, end_date=20250906T045311
[2025-09-06T04:53:11.875+0000] {standard_task_runner.py:109} ERROR - Failed to execute job 221 for task train_model (name 'LogisticRegression' is not defined; 763)
[2025-09-06T04:53:11.927+0000] {local_task_job_runner.py:232} INFO - Task exited with return code 1
[2025-09-06T04:53:11.975+0000] {taskinstance.py:2674} INFO - 0 downstream tasks scheduled from follow-on schedule check
